# Copyright (C) 2001-2022, Python Software Foundation
# This file is distributed under the same license as the Python package.
#
# Translators:
# Matt Wang <mattwang44@gmail.com>, 2022
#
msgid ""
msgstr ""
"Project-Id-Version: Python 3.12\n"
"Report-Msgid-Bugs-To: \n"
"POT-Creation-Date: 2023-07-06 00:19+0000\n"
"PO-Revision-Date: 2022-01-31 21:41+0800\n"
"Last-Translator: Matt Wang <mattwang44@gmail.com>\n"
"Language-Team: Chinese - TAIWAN (https://github.com/python/python-docs-zh-"
"tw)\n"
"Language: zh_TW\n"
"MIME-Version: 1.0\n"
"Content-Type: text/plain; charset=UTF-8\n"
"Content-Transfer-Encoding: 8bit\n"
"Plural-Forms: nplurals=1; plural=0;\n"
"X-Generator: Poedit 3.0.1\n"

#: ../../library/asyncio-exceptions.rst:8
msgid "Exceptions"
msgstr "例外"

#: ../../library/asyncio-exceptions.rst:10
msgid "**Source code:** :source:`Lib/asyncio/exceptions.py`"
msgstr "**原始碼：**\\ :source:`Lib/asyncio/exceptions.py`"

#: ../../library/asyncio-exceptions.rst:16
msgid ""
"A deprecated alias of :exc:`TimeoutError`, raised when the operation has "
"exceeded the given deadline."
msgstr ""
":exc:`TimeoutError` 的一個已被棄用的別名，當操作已超過規定的截止時間時被引"
"發。"

#: ../../library/asyncio-exceptions.rst:21
msgid "This class was made an alias of :exc:`TimeoutError`."
msgstr "此 class 是 :exc:`TimeoutError` 的一個別名。"

#: ../../library/asyncio-exceptions.rst:26
msgid "The operation has been cancelled."
msgstr "該操作已被取消。"

#: ../../library/asyncio-exceptions.rst:28
msgid ""
"This exception can be caught to perform custom operations when asyncio Tasks "
"are cancelled.  In almost all situations the exception must be re-raised."
msgstr ""
"當 asyncio Task 被取消時，可以捕獲此例外以執行客製化操作。在幾乎所有情況下，"
"該例外必須重新被引發。"

#: ../../library/asyncio-exceptions.rst:34
msgid ""
":exc:`CancelledError` is now a subclass of :class:`BaseException` rather "
"than :class:`Exception`."
msgstr ""
":exc:`CancelledError` 現在是 :class:`BaseException` 而非 :class:`Exception` "
"的子類別。"

#: ../../library/asyncio-exceptions.rst:39
msgid "Invalid internal state of :class:`Task` or :class:`Future`."
msgstr ":class:`Task` 或 :class:`Future` 的無效內部狀態。"

#: ../../library/asyncio-exceptions.rst:41
msgid ""
"Can be raised in situations like setting a result value for a *Future* "
"object that already has a result value set."
msgstr "可以在像是為已設定結果值的 *Future* 物件設定結果值的情況下引發。"

#: ../../library/asyncio-exceptions.rst:47
msgid ""
"The \"sendfile\" syscall is not available for the given socket or file type."
msgstr "\"sendfile\" 系統呼叫不適用於給定的 socket 或檔案型別。"

#: ../../library/asyncio-exceptions.rst:50
msgid "A subclass of :exc:`RuntimeError`."
msgstr "一個 :exc:`RuntimeError` 的子類別。"

#: ../../library/asyncio-exceptions.rst:55
msgid "The requested read operation did not complete fully."
msgstr "請求的讀取操作未全部完成。"

#: ../../library/asyncio-exceptions.rst:57
msgid "Raised by the :ref:`asyncio stream APIs<asyncio-streams>`."
msgstr "由 :ref:`asyncio 串流 APIs <asyncio-streams>` 引發。"

#: ../../library/asyncio-exceptions.rst:59
msgid "This exception is a subclass of :exc:`EOFError`."
msgstr "此例外是 :exc:`EOFError` 的子類別。"

#: ../../library/asyncio-exceptions.rst:63
msgid "The total number (:class:`int`) of expected bytes."
msgstr "預期的位元組總數 (\\ :class:`int`\\ )。"

#: ../../library/asyncio-exceptions.rst:67
msgid "A string of :class:`bytes` read before the end of stream was reached."
msgstr "串流結束之前讀取的 :class:`bytes` 字串。"

#: ../../library/asyncio-exceptions.rst:72
msgid "Reached the buffer size limit while looking for a separator."
msgstr "在查詢分隔符號 (separator) 時達到緩衝區 (buffer) 大小限制。"

#: ../../library/asyncio-exceptions.rst:74
msgid "Raised by the :ref:`asyncio stream APIs <asyncio-streams>`."
msgstr "由 :ref:`asyncio 串流 APIs <asyncio-streams>` 引發。"

#: ../../library/asyncio-exceptions.rst:78
msgid "The total number of to be consumed bytes."
msgstr "要消耗的位元組總數。"
